<?xml version="1.0"?>
<robot name="hexapod">

<link name="base_link"/>
<joint name="base_link_to_hexapod_joint" type="fixed">
	<parent link="base_link"/>
	<child link="hexapod_link"/>
</joint>
	<link name="hexapod_link">
 		<visual>
			<geometry>
				<mesh filename="package://akrobat/stl/hexapod_link.stl"/>
			</geometry>
			<origin rpy="0 0 0" xyz="0 0 0"/>
			<material name="grey">
				<color rgba="0.67 0.67 0.67 1"/>
			</material>
		</visual>
			
	</link>
<!-- links-->
<!--.....................leg 1......................-->
	<link name="1_coxa_link">
 		<visual>
			<geometry>
				<mesh filename="package://akrobat/stl/coxa_l_link.stl"/>
			</geometry>
			<origin rpy="0 0 0" xyz="0 0 0"/>
			<material name="grey">
				<color rgba="0.67 0.67 0.67 1"/>
			</material>
		</visual>
	</link>
	<joint name="hexapod_to_1_joint" type="revolute">
		<parent link="hexapod_link"/>
		<child link="1_coxa_link"/>
		<origin xyz="-0.051 0.217 0.0" rpy="0 0 3.14"/>
		<axis xyz="0 0 1"/>
		<limit effort="1000.0" lower="-0.548" upper="0.548" velocity="0.5"/>
	</joint>
	<link name="1_femur_link">
 		<visual>
			<geometry>
				<mesh filename="package://akrobat/stl/femur_link.stl"/>
			</geometry>
			<origin rpy="0 0 0" xyz="0 0 0"/>
			<material name="grey">
				<color rgba="0.67 0.67 0.67 1"/>
			</material>
		</visual>
	</link>
	<joint name="1_coxa_to_femur_joint" type="revolute">
		<parent link="1_coxa_link"/>
		<child link="1_femur_link"/>
		<origin xyz="0.07 0.0 0.0" rpy="0 0 0"/>
		<axis xyz="0 1 0"/>
		<limit effort="1000.0" lower="-1.57" upper="1.57" velocity="0.5"/>
	</joint>
	<link name="1_tibia_link">
 		<visual>
			<geometry>
				<mesh filename="package://akrobat/stl/tibia_link.stl"/>
			</geometry>
			<origin rpy="0 0 0" xyz="0 0 0"/>
			<material name="grey">
				<color rgba="0.67 0.67 0.67 1"/>
			</material>
		</visual>
	</link>
	<joint name="1_femur_to_tibia_joint" type="revolute">
		<parent link="1_femur_link"/>
		<child link="1_tibia_link"/>
		<origin xyz="0.096 0.0 0.0" rpy="0 -1.57 0"/>
		<axis xyz="0 1 0"/>
		<limit effort="1000.0" lower="-1.57" upper="1.57" velocity="0.5"/>
	</joint>
<!-- rechts-->
<!--..................leg 2...................-->
	<link name="2_coxa_link">
 		<visual>
			<geometry>
				<mesh filename="package://akrobat/stl/coxa_r_link.stl"/>
			</geometry>
			<origin rpy="0 0 0" xyz="0 0 0"/>
			<material name="grey">
				<color rgba="0.67 0.67 0.67 1"/>
			</material>
		</visual>
	</link>
	<joint name="hexapod_to_2_joint" type="revolute">
		<parent link="hexapod_link"/>
		<child link="2_coxa_link"/>
		<origin xyz="0.051 0.217 0.0" rpy="0 0 3.14"/>
		<axis xyz="0 0 1"/>
		<limit effort="1000.0" lower="-0.548" upper="0.548" velocity="0.5"/>
	</joint>
 	<link name="2_femur_link">
 		<visual>
			<geometry>
				<mesh filename="package://akrobat/stl/femur_link.stl"/>
			</geometry>
			<origin rpy="0 0 0" xyz="0 0 0"/>
			<material name="grey">
				<color rgba="0.67 0.67 0.67 1"/>
			</material>
		</visual>
	</link>
	<joint name="2_coxa_to_femur_joint" type="revolute">
		<parent link="2_coxa_link"/>
		<child link="2_femur_link"/>
		<origin xyz="-0.07 0.0 0.0" rpy="0 3.14 0"/>
		<axis xyz="0 1 0"/>
		<limit effort="1000.0" lower="-1.57" upper="1.57" velocity="0.5"/>
	</joint>
	<link name="2_tibia_link">
 		<visual>
			<geometry>
				<mesh filename="package://akrobat/stl/tibia_link.stl"/>
			</geometry>
			<origin rpy="0 0 0" xyz="0 0 0"/>
			<material name="grey">
				<color rgba="0.67 0.67 0.67 1"/>
			</material>
		</visual>
	</link>
	<joint name="2_femur_to_tibia_joint" type="revolute">
		<parent link="2_femur_link"/>
		<child link="2_tibia_link"/>
		<origin xyz="0.096 0.0 0.0" rpy="0 -1.57 0"/>
		<axis xyz="0 1 0"/>
		<limit effort="1000.0" lower="-1.57" upper="1.57" velocity="0.5"/>
	</joint>
<!-- links-->
<!--.................. leg 3.......................-->
	<link name="3_coxa_link">
 		<visual>
			<geometry>
				<mesh filename="package://akrobat/stl/coxa_l_link.stl"/>
			</geometry>
			<origin rpy="0 0 0" xyz="0 0 0"/>
			<material name="grey">
				<color rgba="0.67 0.67 0.67 1"/>
			</material>
		</visual>
	</link>
	<joint name="hexapod_to_3_joint" type="revolute">
		<parent link="hexapod_link"/>
		<child link="3_coxa_link"/>
		<origin xyz="-0.051 0.0 0.0" rpy="0 0 3.14"/>
		<axis xyz="0 0 1"/>
		<limit effort="1000.0" lower="-0.548" upper="0.548" velocity="0.5"/>
	</joint>
	<link name="3_femur_link">
 		<visual>
			<geometry>
				<mesh filename="package://akrobat/stl/femur_link.stl"/>
			</geometry>
			<origin rpy="0 0 0" xyz="0 0 0"/>
			<material name="grey">
				<color rgba="0.67 0.67 0.67 1"/>
			</material>
		</visual>
	</link>
	<joint name="3_coxa_to_femur_joint" type="revolute">
		<parent link="3_coxa_link"/>
		<child link="3_femur_link"/>
		<origin xyz="0.07 0.0 0.0" rpy="0 0 0"/>
		<axis xyz="0 1 0"/>
		<limit effort="1000.0" lower="-1.57" upper="1.57" velocity="0.5"/>
	</joint>
	<link name="3_tibia_link">
 		<visual>
			<geometry>
				<mesh filename="package://akrobat/stl/tibia_link.stl"/>
			</geometry>
			<origin rpy="0 0 0" xyz="0 0 0"/>
			<material name="grey">
				<color rgba="0.67 0.67 0.67 1"/>
			</material>
		</visual>
	</link>
	<joint name="3_femur_to_tibia_joint" type="revolute">
		<parent link="3_femur_link"/>
		<child link="3_tibia_link"/>
		<origin xyz="0.096 0.0 0.0" rpy="0 -1.57 0"/>
		<axis xyz="0 1 0"/>
		<limit effort="1000.0" lower="-1.57" upper="1.57" velocity="0.5"/>
	</joint>
<!-- rechts-->
<!--..................leg 4...................-->
	<link name="4_coxa_link">
 		<visual>
			<geometry>
				<mesh filename="package://akrobat/stl/coxa_r_link.stl"/>
			</geometry>
			<origin rpy="0 0 0" xyz="0 0 0"/>
			<material name="grey">
				<color rgba="0.67 0.67 0.67 1"/>
			</material>
		</visual>
	</link>
	<joint name="hexapod_to_4_joint" type="revolute">
		<parent link="hexapod_link"/>
		<child link="4_coxa_link"/>
		<origin xyz="0.051 0.0 0.0" rpy="0 0 3.14"/>
		<axis xyz="0 0 1"/>
		<limit effort="1000.0" lower="-0.548" upper="0.548" velocity="0.5"/>
	</joint>
	<link name="4_femur_link">
 		<visual>
			<geometry>
				<mesh filename="package://akrobat/stl/femur_link.stl"/>
			</geometry>
			<origin rpy="0 0 0" xyz="0 0 0"/>
			<material name="grey">
				<color rgba="0.67 0.67 0.67 1"/>
			</material>
		</visual>
	</link>
	<joint name="4_coxa_to_femur_joint" type="revolute">
		<parent link="4_coxa_link"/>
		<child link="4_femur_link"/>
		<origin xyz="-0.07 0.0 0.0" rpy="0 3.14 0"/>
		<axis xyz="0 1 0"/>
		<limit effort="1000.0" lower="-1.57" upper="1.57" velocity="0.5"/>
	</joint>
	<link name="4_tibia_link">
 		<visual>
			<geometry>
				<mesh filename="package://akrobat/stl/tibia_link.stl"/>
			</geometry>
			<origin rpy="0 0 0" xyz="0 0 0"/>
			<material name="grey">
				<color rgba="0.67 0.67 0.67 1"/>
			</material>
		</visual>
	</link>
	<joint name="4_femur_to_tibia_joint" type="revolute">
		<parent link="4_femur_link"/>
		<child link="4_tibia_link"/>
		<origin xyz="0.096 0.0 0.0" rpy="0 -1.57 0"/>
		<axis xyz="0 1 0"/>
		<limit effort="1000.0" lower="-1.57" upper="1.57" velocity="0.5"/>
	</joint>
<!-- links-->
<!--..................leg 5...................-->
	<link name="5_coxa_link">
 		<visual>
			<geometry>
				<mesh filename="package://akrobat/stl/coxa_l_link.stl"/>
			</geometry>
			<origin rpy="0 0 0" xyz="0 0 0"/>
			<material name="grey">
				<color rgba="0.67 0.67 0.67 1"/>
			</material>
		</visual>
	</link>
	<joint name="hexapod_to_5_joint" type="revolute">
		<parent link="hexapod_link"/>
		<child link="5_coxa_link"/>
		<origin xyz="-0.051 -0.217 0.0" rpy="0 0 3.14"/>
		<axis xyz="0 0 1"/>
		<limit effort="1000.0" lower="-0.548" upper="0.548" velocity="0.5"/>
	</joint>
	<link name="5_femur_link">
 		<visual>
			<geometry>
				<mesh filename="package://akrobat/stl/femur_link.stl"/>
			</geometry>
			<origin rpy="0 0 0" xyz="0 0 0"/>
			<material name="grey">
				<color rgba="0.67 0.67 0.67 1"/>
			</material>
		</visual>
	</link>
	<joint name="5_coxa_to_femur_joint" type="revolute">
		<parent link="5_coxa_link"/>
		<child link="5_femur_link"/>
		<origin xyz="0.07 0.0 0.0" rpy="0 0 0"/>
		<axis xyz="0 1 0"/>
		<limit effort="1000.0" lower="-1.57" upper="1.57" velocity="0.5"/>
	</joint>
	<link name="5_tibia_link">
 		<visual>
			<geometry>
				<mesh filename="package://akrobat/stl/tibia_link.stl"/>
			</geometry>
			<origin rpy="0 0 0" xyz="0 0 0"/>
			<material name="grey">
				<color rgba="0.67 0.67 0.67 1"/>
			</material>
		</visual>
	</link>
	<joint name="5_femur_to_tibia_joint" type="revolute">
		<parent link="5_femur_link"/>
		<child link="5_tibia_link"/>
		<origin xyz="0.096 0.0 0.0" rpy="0 -1.57 0"/>
		<axis xyz="0 1 0"/>
		<limit effort="1000.0" lower="-1.57" upper="1.57" velocity="0.5"/>
	</joint>

<!-- rechts-->
<!--..................leg 6...................-->
	<link name="6_coxa_link">
 		<visual>
			<geometry>
				<mesh filename="package://akrobat/stl/coxa_r_link.stl"/>
			</geometry>
			<origin rpy="0 0 0" xyz="0 0 0"/>
			<material name="grey">
				<color rgba="0.67 0.67 0.67 1"/>
			</material>
		</visual>
	</link>
	<joint name="hexapod_to_6_joint" type="revolute">
		<parent link="hexapod_link"/>
		<child link="6_coxa_link"/>
		<origin xyz="0.051 -0.217 0.0" rpy="0 0 3.14"/>
		<axis xyz="0 0 1"/>
		<limit effort="1000.0" lower="-0.548" upper="0.548" velocity="0.5"/>
	</joint>
	<link name="6_femur_link">
 		<visual>
			<geometry>
				<mesh filename="package://akrobat/stl/femur_link.stl"/>
			</geometry>
			<origin rpy="0 0 0" xyz="0 0 0"/>
			<material name="grey">
				<color rgba="0.67 0.67 0.67 1"/>
			</material>
		</visual>
	</link>
	<joint name="6_coxa_to_femur_joint" type="revolute">
		<parent link="6_coxa_link"/>
		<child link="6_femur_link"/>
		<origin xyz="-0.07 0.0 0.0" rpy="0 3.14 0"/>
		<axis xyz="0 1 0"/>
		<limit effort="1000.0" lower="-1.57" upper="1.57" velocity="0.5"/>
	</joint>
	<link name="6_tibia_link">
 		<visual>
			<geometry>
				<mesh filename="package://akrobat/stl/tibia_link.stl"/>
			</geometry>
			<origin rpy="0 0 0" xyz="0 0 0"/>
			<material name="grey">
				<color rgba="0.67 0.67 0.67 1"/>
			</material>
		</visual>
	</link>
	<joint name="6_femur_to_tibia_joint" type="revolute">
		<parent link="6_femur_link"/>
		<child link="6_tibia_link"/>
		<origin xyz="0.096 0.0 0.0" rpy="0 -1.57 0"/>
		<axis xyz="0 1 0"/>
		<limit effort="1000.0" lower="-1.57" upper="1.57" velocity="0.5"/>
	</joint>
</robot>
