<?xml version="1.0"?>
<robot name="Sechsbeiner">
	<link name="base_link">
 		<visual>
			<geometry>
				<mesh filename="package://akrobat/stl/hexapod_link.stl"/>
			</geometry>
			<origin rpy="0 0 0" xyz="0 0 0"/>
			<material name="grey">
				<color rgba="0.67 0.67 0.67 1"/>
			</material>
		</visual>
			
	</link>

	<link name="base_mitte_link">
 		<visual>
			<geometry>
				<box size="0.101 0.030 0.04"/>
			</geometry>
			<origin rpy="0 0 0" xyz="0 0 0"/>
			<material name="black">
				<color rgba="0 0 0 1"/>
			</material>
		</visual>
	</link>

	<joint name="base_to_base_mitte" type="fixed">
		<parent link="base_link"/>

		<child link="base_mitte_link"/>
		<origin xyz="0 0.099 0"/>
	</joint>

	<link name="base_hinten_link">
 		<visual>
			<geometry>
				<box size="0.101 0.030 0.04"/>
			</geometry>
			<origin rpy="0 0 0" xyz="0 0 0"/>
			<material name="black"/>
		</visual>
	</link>

	<joint name="base_to_base_hinten" type="fixed">
		<parent link="base_link"/>
		<child link="base_hinten_link"/>
		<origin xyz="0 -0.099 0"/>
	</joint>

	<link name="base_zwei_link">
 		<visual>
			<geometry>
				<box size="0.102 0.168 0.051"/>
			</geometry>
			<origin rpy="0 0 0" xyz="0 0 0"/>
			<material name="grey">
				<color rgba="0.67 0.67 0.67 1"/>
			</material>
		</visual>
			
	</link>
	
	<joint name="base_mitte_to_base_zwei" type="fixed">
		<parent link="base_mitte_link"/>
		<child link="base_zwei_link"/>
		<origin xyz="0 0.099 0"/>
	</joint>

	<link name="base_vorne_link">
 		<visual>
			<geometry>
				<box size="0.101 0.030 0.04"/>
			</geometry>
			<origin rpy="0 0 0" xyz="0 0 0"/>
			<material name="black">
				<color rgba="0 0 0 1"/>
			</material>
		</visual>
	</link>

	<joint name="base_zwei_to_base_vorne" type="fixed">
		<parent link="base_zwei_link"/>
		<child link="base_vorne_link"/>
		<origin xyz="0 0.099 0"/>
	</joint>


<!-- BEIN LINKS MITTE -->

	<link name="bein_links_1a_link">
 		<visual>
			<geometry>
				<box size="0.0351 0.0275 0.0063"/>
			</geometry>
			<origin rpy="0 0 0" xyz="0 0 0"/>
			<material name="grey"/>
		</visual>
	</link>

	<joint name="base_mitte_to_bein_links_1a" type="revolute">
		<parent link="base_mitte_link"/>
		<child link="bein_links_1a_link"/>
		<origin xyz="0.0507505 0 0.02315" rpy="0 0 0"/>
		<axis xyz="0 0 1"/>
		<limit effort="1000.0" lower="-0.548" upper="0.548" velocity="0.5"/>
	</joint>

	
	<link name="bein_links_1b_link">
 		<visual>
			<geometry>
				<box size="0.0351 0.0275 0.0063"/>
			</geometry>
			<origin rpy="0 0 0" xyz="0 0 0"/>
			<material name="grey"/>
		</visual>
	</link>

	<link name="bein_links_1c_link">
 		<visual>
			<geometry>
				<box size="0.0063 0.0275 0.04"/>
			</geometry>
			<origin rpy="0 0 0" xyz="0 0 0"/>
			<material name="grey"/>
		</visual>
	</link>

	<joint name="bein_links_1a_to_bein_links_1c" type="fixed">
		<parent link="bein_links_1a_link"/>
		<child link="bein_links_1c_link"/>
		<origin xyz="0.01555 0 -0.0233"/>
	</joint>

	<joint name="bein_links_1b_to_bein_links_1c" type="fixed">
		<parent link="bein_links_1c_link"/>
		<child link="bein_links_1b_link"/>
		<origin xyz="-0.01555 0 -0.0233"/>
	</joint>

	<link name="bein_links_2a_link">
 		<visual>
			<geometry>
				<box size="0.0063 0.04 0.0275"/>
			</geometry>
			<origin rpy="0 0 0" xyz="0 0 0"/>
			<material name="grey"/>
		</visual>
	</link>

	<joint name="bein_links_1c_to_bein_links_2a" type="fixed">
		<parent link="bein_links_1c_link"/>
		<child link="bein_links_2a_link"/>
		<origin xyz="0.0063 0 0"/>
		</joint>

	<link name="bein_links_2b_link">
 		<visual>
			<geometry>
				<box size="0.0351 0.0063 0.0275"/>0
			</geometry>
			<origin rpy="0 0 0" xyz="0 0 0"/>
			<material name="grey"/>
		</visual>
	</link>

	<joint name="bein_links_2a_to_bein_links_2b" type="fixed">
		<parent link="bein_links_2a_link"/>
		<child link="bein_links_2b_link"/>
		<origin xyz="0.01855 0.01685 0"/>
	</joint>

	<link name="bein_links_2c_link">
 		<visual>
			<geometry>
				<box size="0.0351 0.0063 0.0275"/>0
			</geometry>
			<origin rpy="0 0 0" xyz="0 0 0"/>
			<material name="grey"/>
		</visual>
	</link>

	<joint name="bein_links_2a_to_bein_links_2c" type="fixed">
		<parent link="bein_links_2a_link"/>
		<child link="bein_links_2c_link"/>
		<origin xyz="0.01855 -0.01685 0"/>
	</joint>

	<link name="bein_links_2d_link">
 		<visual>
			<geometry>
				<box size="0.0505 0.03 0.04"/>
			</geometry>
			<origin rpy="0 0 0" xyz="0 0 0"/>
			<material name="black"/>
		</visual>
	</link>

	<joint name="bein_links_2b_to_bein_links_2d" type="revolute">
		<parent link="bein_links_2b_link"/>
		<child link="bein_links_2d_link"/>
		<origin xyz="0.0255005 -0.01815 0"/>
		<axis xyz="0 1 0"/>
		<limit effort="1000.0" lower="-0.548" upper="0.548" velocity="0.5"/>
	</joint>

	<link name="bein_links_3a_link">
 		<visual>
			<geometry>
				<box size="0.0063 0.04 0.0275"/>
			</geometry>
			<origin rpy="0 0 0" xyz="0 0 0"/>
			<material name="grey"/>
		</visual>
	</link>

	<joint name="bein_links_2d_to_bein_links_3a" type="fixed">
		<parent link="bein_links_2d_link"/>
		<child link="bein_links_3a_link"/>
		<origin xyz="0.0284 0 0"/>
	</joint>

	

	<link name="bein_links_3b_link">
 		<visual>
			<geometry>
				<box size="0.0351 0.0063 0.0275"/>0
			</geometry>
			<origin rpy="0 0 0" xyz="0 0 0"/>
			<material name="grey"/>
		</visual>
	</link>

	<joint name="bein_links_3a_to_bein_links_3b" type="fixed">
		<parent link="bein_links_3a_link"/>
		<child link="bein_links_3b_link"/>
		<origin xyz="0.01855 0.01685 0"/>
	</joint>

	<link name="bein_links_3c_link">
 		<visual>
			<geometry>
				<box size="0.0351 0.0063 0.0275"/>0
			</geometry>
			<origin rpy="0 0 0" xyz="0 0 0"/>
			<material name="grey"/>
		</visual>
	</link>

	<joint name="bein_links_3a_to_bein_links_3c" type="fixed">
		<parent link="bein_links_3a_link"/>
		<child link="bein_links_3c_link"/>
		<origin xyz="0.01855 -0.01685 0"/>
	</joint>

	<link name="bein_links_3d_link">
 		<visual>
			<geometry>
				<box size="0.04 0.03 0.0505"/>
			</geometry>
			<origin rpy="0 0 0" xyz="0 0 0"/>
			<material name="black"/>
		</visual>
	</link>

	<joint name="bein_links_3b_to_bein_links_3d" type="revolute">
		<parent link="bein_links_3b_link"/>
		<child link="bein_links_3d_link"/>
		<origin xyz="0.022505 -0.01815 -0.01"/>
		<axis xyz="0 1 0"/>
		<limit effort="1000.0" lower="-0.548" upper="0.548" velocity="0.5"/>
	</joint>

	<link name="bein_links_4a_link">
 		<visual>
			<geometry>
				<box size="0.04 0.03 0.0216"/>
			</geometry>
			<origin rpy="0 0 0" xyz="0 0 0"/>
			<material name="grey"/>
		</visual>
	</link>

	<joint name="bein_links_3d_to_bein_links_4a" type="fixed">
		<parent link="bein_links_3d_link"/>
		<child link="bein_links_4a_link"/>
		<origin xyz="0 0 -0.03578"/>
	</joint>

	<link name="bein_links_4b_link">
 		<visual>
			<geometry>
				<cylinder length="0.082" radius="0.00375"/>
			</geometry>
			<origin rpy="0 0 0" xyz="0 0 0"/>
			<material name="grey"/>
		</visual>
	</link>

	<joint name="bein_links_4a_to_bein_links_4b" type="fixed">
		<parent link="bein_links_4a_link"/>
		<child link="bein_links_4b_link"/>
		<origin xyz="0 0 -0.05153"/>
	</joint>

	<link name="bein_links_4c_link">
 		<visual>
			<geometry>
				<sphere radius="0.004"/>
			</geometry>
			<origin rpy="0 0 0" xyz="0 0 0"/>
			<material name="black"/>
		</visual>
	</link>

	<joint name="bein_links_4b_to_bein_links_4c" type="fixed">
		<parent link="bein_links_4b_link"/>
		<child link="bein_links_4c_link"/>
		<origin xyz="0 0 -0.043"/>
	</joint>





<!-- BEIN LINKS HINTEN -->




	<link name="bein_links_hinten_1a_link">
 		<visual>
			<geometry>
				<box size="0.0351 0.0275 0.0063"/>
			</geometry>
			<origin rpy="0 0 0" xyz="0 0 0"/>
			<material name="grey"/>
		</visual>
	</link>

	<joint name="base_hinten_to_bein_links_hinten_1a" type="revolute">
		<parent link="base_hinten_link"/>
		<child link="bein_links_hinten_1a_link"/>
		<origin xyz="0.0507505 0 0.02315" rpy="0 0 0"/>
		<axis xyz="0 0 1"/>
		<limit effort="1000.0" lower="-0.548" upper="0.548" velocity="0.5"/>
	</joint>

	<link name="bein_links_hinten_1b_link">
 		<visual>
			<geometry>
				<box size="0.0351 0.0275 0.0063"/>
			</geometry>
			<origin rpy="0 0 0" xyz="0 0 0"/>
			<material name="grey"/>
		</visual>
	</link>

	<link name="bein_links_hinten_1c_link">
 		<visual>
			<geometry>
				<box size="0.0063 0.0275 0.04"/>
			</geometry>
			<origin rpy="0 0 0" xyz="0 0 0"/>
			<material name="grey"/>
		</visual>
	</link>

	<joint name="bein_links_hinten_1a_to_bein_links_hinten_1c" type="fixed">
		<parent link="bein_links_hinten_1a_link"/>
		<child link="bein_links_hinten_1c_link"/>
		<origin xyz="0.01555 0 -0.0233"/>
	</joint>

	<joint name="bein_links_hinten_1b_to_bein_links_hinten_1c" type="fixed">
		<parent link="bein_links_hinten_1c_link"/>
		<child link="bein_links_hinten_1b_link"/>
		<origin xyz="-0.01555 0 -0.0233"/>
	</joint>

	<link name="bein_links_hinten_2a_link">
 		<visual>
			<geometry>
				<box size="0.0063 0.04 0.0275"/>
			</geometry>
			<origin rpy="0 0 0" xyz="0 0 0"/>
			<material name="grey"/>
		</visual>
	</link>

	<joint name="bein_links_hinten_1c_to_bein_links_hinten_2a" type="fixed">
		<parent link="bein_links_hinten_1c_link"/>
		<child link="bein_links_hinten_2a_link"/>
		<origin xyz="0.0063 0 0"/>
		</joint>

	<link name="bein_links_hinten_2b_link">
 		<visual>
			<geometry>
				<box size="0.0351 0.0063 0.0275"/>0
			</geometry>
			<origin rpy="0 0 0" xyz="0 0 0"/>
			<material name="grey"/>
		</visual>
	</link>

	<joint name="bein_links_hinten_2a_to_bein_links_hinten_2b" type="fixed">
		<parent link="bein_links_hinten_2a_link"/>
		<child link="bein_links_hinten_2b_link"/>
		<origin xyz="0.01855 0.01685 0"/>
	</joint>

	<link name="bein_links_hinten_2c_link">
 		<visual>
			<geometry>
				<box size="0.0351 0.0063 0.0275"/>0
			</geometry>
			<origin rpy="0 0 0" xyz="0 0 0"/>
			<material name="grey"/>
		</visual>
	</link>

	<joint name="bein_links_hinten_2a_to_bein_links_hinten_2c" type="fixed">
		<parent link="bein_links_hinten_2a_link"/>
		<child link="bein_links_hinten_2c_link"/>
		<origin xyz="0.01855 -0.01685 0"/>
	</joint>

	<link name="bein_links_hinten_2d_link">
 		<visual>
			<geometry>
				<box size="0.0505 0.03 0.04"/>
			</geometry>
			<origin rpy="0 0 0" xyz="0 0 0"/>
			<material name="black"/>
		</visual>
	</link>

	<joint name="bein_links_hinten_2b_to_bein_links_hinten_2d" type="revolute">
		<parent link="bein_links_hinten_2b_link"/>
		<child link="bein_links_hinten_2d_link"/>
		<origin xyz="0.0255005 -0.01815 0"/>
		<axis xyz="0 1 0"/>
		<limit effort="1000.0" lower="-0.548" upper="0.548" velocity="0.5"/>
	</joint>

	<link name="bein_links_hinten_3a_link">
 		<visual>
			<geometry>
				<box size="0.0063 0.04 0.0275"/>
			</geometry>
			<origin rpy="0 0 0" xyz="0 0 0"/>
			<material name="grey"/>
		</visual>
	</link>

	<joint name="bein_links_hinten_2d_to_bein_links_hinten_3a" type="fixed">
		<parent link="bein_links_hinten_2d_link"/>
		<child link="bein_links_hinten_3a_link"/>
		<origin xyz="0.0284 0 0"/>
	</joint>

	

	<link name="bein_links_hinten_3b_link">
 		<visual>
			<geometry>
				<box size="0.0351 0.0063 0.0275"/>0
			</geometry>
			<origin rpy="0 0 0" xyz="0 0 0"/>
			<material name="grey"/>
		</visual>
	</link>

	<joint name="bein_links_hinten_3a_to_bein_links_hinten_3b" type="fixed">
		<parent link="bein_links_hinten_3a_link"/>
		<child link="bein_links_hinten_3b_link"/>
		<origin xyz="0.01855 0.01685 0"/>
	</joint>

	<link name="bein_links_hinten_3c_link">
 		<visual>
			<geometry>
				<box size="0.0351 0.0063 0.0275"/>0
			</geometry>
			<origin rpy="0 0 0" xyz="0 0 0"/>
			<material name="grey"/>
		</visual>
	</link>

	<joint name="bein_links_hinten_3a_to_bein_links_hinten_3c" type="fixed">
		<parent link="bein_links_hinten_3a_link"/>
		<child link="bein_links_hinten_3c_link"/>
		<origin xyz="0.01855 -0.01685 0"/>
	</joint>

	<link name="bein_links_hinten_3d_link">
 		<visual>
			<geometry>
				<box size="0.04 0.03 0.0505"/>
			</geometry>
			<origin rpy="0 0 0" xyz="0 0 0"/>
			<material name="black"/>
		</visual>
	</link>

	<joint name="bein_links_hinten_3b_to_bein_links_hinten_3d" type="revolute">
		<parent link="bein_links_hinten_3b_link"/>
		<child link="bein_links_hinten_3d_link"/>
		<origin xyz="0.022505 -0.01815 -0.01"/>
		<axis xyz="0 1 0"/>
		<limit effort="1000.0" lower="-0.548" upper="0.548" velocity="0.5"/>
	</joint>

	<link name="bein_links_hinten_4a_link">
 		<visual>
			<geometry>
				<box size="0.04 0.03 0.0216"/>
			</geometry>
			<origin rpy="0 0 0" xyz="0 0 0"/>
			<material name="grey"/>
		</visual>
	</link>

	<joint name="bein_links_hinten_3d_to_bein_links_hinten_4a" type="fixed">
		<parent link="bein_links_hinten_3d_link"/>
		<child link="bein_links_hinten_4a_link"/>
		<origin xyz="0 0 -0.03578"/>
	</joint>

	<link name="bein_links_hinten_4b_link">
 		<visual>
			<geometry>
				<cylinder length="0.082" radius="0.00375"/>
			</geometry>
			<origin rpy="0 0 0" xyz="0 0 0"/>
			<material name="grey"/>
		</visual>
	</link>

	<joint name="bein_links_hinten_4a_to_bein_links_hinten_4b" type="fixed">
		<parent link="bein_links_hinten_4a_link"/>
		<child link="bein_links_hinten_4b_link"/>
		<origin xyz="0 0 -0.05153"/>
	</joint>

	<link name="bein_links_hinten_4c_link">
 		<visual>
			<geometry>
				<sphere radius="0.004"/>
			</geometry>
			<origin rpy="0 0 0" xyz="0 0 0"/>
			<material name="black"/>
		</visual>
	</link>

	<joint name="bein_links_hinten_4b_to_bein_links_hinten_4c" type="fixed">
		<parent link="bein_links_hinten_4b_link"/>
		<child link="bein_links_hinten_4c_link"/>
		<origin xyz="0 0 -0.043"/>
	</joint>



<!-- BEIN LINKS VORNE -->




	<link name="bein_links_vorne_1a_link">
 		<visual>
			<geometry>
				<box size="0.0351 0.0275 0.0063"/>
			</geometry>
			<origin rpy="0 0 0" xyz="0 0 0"/>
			<material name="grey"/>
		</visual>
	</link>

	<joint name="base_vorne_to_bein_links_vorne_1a" type="revolute">
		<parent link="base_vorne_link"/>
		<child link="bein_links_vorne_1a_link"/>
		<origin xyz="0.0507505 0 0.02315" rpy="0 0 0"/>
		<axis xyz="0 0 1"/>
		<limit effort="1000.0" lower="-0.548" upper="0.548" velocity="0.5"/>
	</joint>

	<link name="bein_links_vorne_1b_link">
 		<visual>
			<geometry>
				<box size="0.0351 0.0275 0.0063"/>
			</geometry>
			<origin rpy="0 0 0" xyz="0 0 0"/>
			<material name="grey"/>
		</visual>
	</link>

	<link name="bein_links_vorne_1c_link">
 		<visual>
			<geometry>
				<box size="0.0063 0.0275 0.04"/>
			</geometry>
			<origin rpy="0 0 0" xyz="0 0 0"/>
			<material name="grey"/>
		</visual>
	</link>

	<joint name="bein_links_vorne_1a_to_bein_links_vorne_1c" type="fixed">
		<parent link="bein_links_vorne_1a_link"/>
		<child link="bein_links_vorne_1c_link"/>
		<origin xyz="0.01555 0 -0.0233"/>
	</joint>

	<joint name="bein_links_vorne_1b_to_bein_links_vorne_1c" type="fixed">
		<parent link="bein_links_vorne_1c_link"/>
		<child link="bein_links_vorne_1b_link"/>
		<origin xyz="-0.01555 0 -0.0233"/>
	</joint>

	<link name="bein_links_vorne_2a_link">
 		<visual>
			<geometry>
				<box size="0.0063 0.04 0.0275"/>
			</geometry>
			<origin rpy="0 0 0" xyz="0 0 0"/>
			<material name="grey"/>
		</visual>
	</link>

	<joint name="bein_links_vorne_1c_to_bein_links_vorne_2a" type="fixed">
		<parent link="bein_links_vorne_1c_link"/>
		<child link="bein_links_vorne_2a_link"/>
		<origin xyz="0.0063 0 0"/>
		</joint>

	<link name="bein_links_vorne_2b_link">
 		<visual>
			<geometry>
				<box size="0.0351 0.0063 0.0275"/>0
			</geometry>
			<origin rpy="0 0 0" xyz="0 0 0"/>
			<material name="grey"/>
		</visual>
	</link>

	<joint name="bein_links_vorne_2a_to_bein_links_vorne_2b" type="fixed">
		<parent link="bein_links_vorne_2a_link"/>
		<child link="bein_links_vorne_2b_link"/>
		<origin xyz="0.01855 0.01685 0"/>
	</joint>

	<link name="bein_links_vorne_2c_link">
 		<visual>
			<geometry>
				<box size="0.0351 0.0063 0.0275"/>0
			</geometry>
			<origin rpy="0 0 0" xyz="0 0 0"/>
			<material name="grey"/>
		</visual>
	</link>

	<joint name="bein_links_vorne_2a_to_bein_links_vorne_2c" type="fixed">
		<parent link="bein_links_vorne_2a_link"/>
		<child link="bein_links_vorne_2c_link"/>
		<origin xyz="0.01855 -0.01685 0"/>
	</joint>

	<link name="bein_links_vorne_2d_link">
 		<visual>
			<geometry>
				<box size="0.0505 0.03 0.04"/>
			</geometry>
			<origin rpy="0 0 0" xyz="0 0 0"/>
			<material name="black"/>
		</visual>
	</link>

	<joint name="bein_links_vorne_2b_to_bein_links_vorne_2d" type="revolute">
		<parent link="bein_links_vorne_2b_link"/>
		<child link="bein_links_vorne_2d_link"/>
		<origin xyz="0.0255005 -0.01815 0"/>
		<axis xyz="0 1 0"/>
		<limit effort="1000.0" lower="-0.548" upper="0.548" velocity="0.5"/>
	</joint>

	<link name="bein_links_vorne_3a_link">
 		<visual>
			<geometry>
				<box size="0.0063 0.04 0.0275"/>
			</geometry>
			<origin rpy="0 0 0" xyz="0 0 0"/>
			<material name="grey"/>
		</visual>
	</link>

	<joint name="bein_links_vorne_2d_to_bein_links_vorne_3a" type="fixed">
		<parent link="bein_links_vorne_2d_link"/>
		<child link="bein_links_vorne_3a_link"/>
		<origin xyz="0.0284 0 0"/>
	</joint>

	

	<link name="bein_links_vorne_3b_link">
 		<visual>
			<geometry>
				<box size="0.0351 0.0063 0.0275"/>0
			</geometry>
			<origin rpy="0 0 0" xyz="0 0 0"/>
			<material name="grey"/>
		</visual>
	</link>

	<joint name="bein_links_vorne_3a_to_bein_links_vorne_3b" type="fixed">
		<parent link="bein_links_vorne_3a_link"/>
		<child link="bein_links_vorne_3b_link"/>
		<origin xyz="0.01855 0.01685 0"/>
	</joint>

	<link name="bein_links_vorne_3c_link">
 		<visual>
			<geometry>
				<box size="0.0351 0.0063 0.0275"/>0
			</geometry>
			<origin rpy="0 0 0" xyz="0 0 0"/>
			<material name="grey"/>
		</visual>
	</link>

	<joint name="bein_links_vorne_3a_to_bein_links_vorne_3c" type="fixed">
		<parent link="bein_links_vorne_3a_link"/>
		<child link="bein_links_vorne_3c_link"/>
		<origin xyz="0.01855 -0.01685 0"/>
	</joint>

	<link name="bein_links_vorne_3d_link">
 		<visual>
			<geometry>
				<box size="0.04 0.03 0.0505"/>
			</geometry>
			<origin rpy="0 0 0" xyz="0 0 0"/>
			<material name="black"/>
		</visual>
	</link>

	<joint name="bein_links_vorne_3b_to_bein_links_vorne_3d" type="revolute">
		<parent link="bein_links_vorne_3b_link"/>
		<child link="bein_links_vorne_3d_link"/>
		<origin xyz="0.022505 -0.01815 -0.01"/>
		<axis xyz="0 1 0"/>
		<limit effort="1000.0" lower="-0.548" upper="0.548" velocity="0.5"/>
	</joint>

	<link name="bein_links_vorne_4a_link">
 		<visual>
			<geometry>
				<box size="0.04 0.03 0.0216"/>
			</geometry>
			<origin rpy="0 0 0" xyz="0 0 0"/>
			<material name="grey"/>
		</visual>
	</link>

	<joint name="bein_links_vorne_3d_to_bein_links_vorne_4a" type="fixed">
		<parent link="bein_links_vorne_3d_link"/>
		<child link="bein_links_vorne_4a_link"/>
		<origin xyz="0 0 -0.03578"/>
	</joint>

	<link name="bein_links_vorne_4b_link">
 		<visual>
			<geometry>
				<cylinder length="0.082" radius="0.00375"/>
			</geometry>
			<origin rpy="0 0 0" xyz="0 0 0"/>
			<material name="grey"/>
		</visual>
	</link>

	<joint name="bein_links_vorne_4a_to_bein_links_vorne_4b" type="fixed">
		<parent link="bein_links_vorne_4a_link"/>
		<child link="bein_links_vorne_4b_link"/>
		<origin xyz="0 0 -0.05153"/>
	</joint>

	<link name="bein_links_vorne_4c_link">
 		<visual>
			<geometry>
				<sphere radius="0.004"/>
			</geometry>
			<origin rpy="0 0 0" xyz="0 0 0"/>
			<material name="black"/>
		</visual>
	</link>

	<joint name="bein_links_vorne_4b_to_bein_links_vorne_4c" type="fixed">
		<parent link="bein_links_vorne_4b_link"/>
		<child link="bein_links_vorne_4c_link"/>
		<origin xyz="0 0 -0.043"/>
	</joint>



<!-- BEIN RECHTS VORNE -->



	<link name="bein_rechts_vorne_1a_link">
 		<visual>
			<geometry>
				<box size="0.0351 0.0275 0.0063"/>
			</geometry>
			<origin rpy="0 0 0" xyz="0 0 0"/>
			<material name="grey"/>
		</visual>
	</link>

	<joint name="base_vorne_to_bein_rechts_vorne_1a" type="revolute">
		<parent link="base_vorne_link"/>
		<child link="bein_rechts_vorne_1a_link"/>
		<origin xyz="-0.0507505 0 0.02315" rpy="0 0 0"/>
		<axis xyz="0 0 1"/>
		<limit effort="1000.0" lower="-0.548" upper="0.548" velocity="0.5"/>
	</joint>

	<link name="bein_rechts_vorne_1b_link">
 		<visual>
			<geometry>
				<box size="0.0351 0.0275 0.0063"/>
			</geometry>
			<origin rpy="0 0 0" xyz="0 0 0"/>
			<material name="grey"/>
		</visual>
	</link>

	<link name="bein_rechts_vorne_1c_link">
 		<visual>
			<geometry>
				<box size="0.0063 0.0275 0.04"/>
			</geometry>
			<origin rpy="0 0 0" xyz="0 0 0"/>
			<material name="grey"/>
		</visual>
	</link>

	<joint name="bein_rechts_vorne_1a_to_bein_rechts_vorne_1c" type="fixed">
		<parent link="bein_rechts_vorne_1a_link"/>
		<child link="bein_rechts_vorne_1c_link"/>
		<origin xyz="-0.01555 0 -0.0233"/>
	</joint>

	<joint name="bein_rechts_vorne_1b_to_bein_rechts_vorne_1c" type="fixed">
		<parent link="bein_rechts_vorne_1c_link"/>
		<child link="bein_rechts_vorne_1b_link"/>
		<origin xyz="0.01555 0 -0.0233"/>
	</joint>

	<link name="bein_rechts_vorne_2a_link">
 		<visual>
			<geometry>
				<box size="0.0063 0.04 0.0275"/>
			</geometry>
			<origin rpy="0 0 0" xyz="0 0 0"/>
			<material name="grey"/>
		</visual>
	</link>

	<joint name="bein_rechts_vorne_1c_to_bein_rechts_vorne_2a" type="fixed">
		<parent link="bein_rechts_vorne_1c_link"/>
		<child link="bein_rechts_vorne_2a_link"/>
		<origin xyz="-0.0063 0 0"/>
		</joint>

	<link name="bein_rechts_vorne_2b_link">
 		<visual>
			<geometry>
				<box size="0.0351 0.0063 0.0275"/>0
			</geometry>
			<origin rpy="0 0 0" xyz="0 0 0"/>
			<material name="grey"/>
		</visual>
	</link>

	<joint name="bein_rechts_vorne_2a_to_bein_rechts_vorne_2b" type="fixed">
		<parent link="bein_rechts_vorne_2a_link"/>
		<child link="bein_rechts_vorne_2b_link"/>
		<origin xyz="-0.01855 0.01685 0"/>
	</joint>

	<link name="bein_rechts_vorne_2c_link">
 		<visual>
			<geometry>
				<box size="0.0351 0.0063 0.0275"/>0
			</geometry>
			<origin rpy="0 0 0" xyz="0 0 0"/>
			<material name="grey"/>
		</visual>
	</link>

	<joint name="bein_rechts_vorne_2a_to_bein_rechts_vorne_2c" type="fixed">
		<parent link="bein_rechts_vorne_2a_link"/>
		<child link="bein_rechts_vorne_2c_link"/>
		<origin xyz="-0.01855 -0.01685 0"/>
	</joint>

	<link name="bein_rechts_vorne_2d_link">
 		<visual>
			<geometry>
				<box size="0.0505 0.03 0.04"/>
			</geometry>
			<origin rpy="0 0 0" xyz="0 0 0"/>
			<material name="black"/>
		</visual>
	</link>

	<joint name="bein_rechts_vorne_2b_to_bein_rechts_vorne_2d" type="revolute">
		<parent link="bein_rechts_vorne_2b_link"/>
		<child link="bein_rechts_vorne_2d_link"/>
		<origin xyz="-0.0255005 -0.01815 0"/>
		<axis xyz="0 1 0"/>
		<limit effort="1000.0" lower="-0.548" upper="0.548" velocity="0.5"/>
	</joint>

	<link name="bein_rechts_vorne_3a_link">
 		<visual>
			<geometry>
				<box size="0.0063 0.04 0.0275"/>
			</geometry>
			<origin rpy="0 0 0" xyz="0 0 0"/>
			<material name="grey"/>
		</visual>
	</link>

	<joint name="bein_rechts_vorne_2d_to_bein_rechts_vorne_3a" type="fixed">
		<parent link="bein_rechts_vorne_2d_link"/>
		<child link="bein_rechts_vorne_3a_link"/>
		<origin xyz="-0.0284 0 0"/>
	</joint>

	<link name="bein_rechts_vorne_3b_link">
 		<visual>
			<geometry>
				<box size="0.0351 0.0063 0.0275"/>0
			</geometry>
			<origin rpy="0 0 0" xyz="0 0 0"/>
			<material name="grey"/>
		</visual>
	</link>

	<joint name="bein_rechts_vorne_3a_to_bein_rechts_vorne_3b" type="fixed">
		<parent link="bein_rechts_vorne_3a_link"/>
		<child link="bein_rechts_vorne_3b_link"/>
		<origin xyz="-0.01855 0.01685 0"/>
	</joint>

	<link name="bein_rechts_vorne_3c_link">
 		<visual>
			<geometry>
				<box size="0.0351 0.0063 0.0275"/>0
			</geometry>
			<origin rpy="0 0 0" xyz="0 0 0"/>
			<material name="grey"/>
		</visual>
	</link>

	<joint name="bein_rechts_vorne_3a_to_bein_rechts_vorne_3c" type="fixed">
		<parent link="bein_rechts_vorne_3a_link"/>
		<child link="bein_rechts_vorne_3c_link"/>
		<origin xyz="-0.01855 -0.01685 0"/>
	</joint>

	<link name="bein_rechts_vorne_3d_link">
 		<visual>
			<geometry>
				<box size="0.04 0.03 0.0505"/>
			</geometry>
			<origin rpy="0 0 0" xyz="0 0 0"/>
			<material name="black"/>
		</visual>
	</link>

	<joint name="bein_rechts_vorne_3b_to_bein_rechts_vorne_3d" type="revolute">
		<parent link="bein_rechts_vorne_3b_link"/>
		<child link="bein_rechts_vorne_3d_link"/>
		<origin xyz="-0.022505 -0.01815 -0.01"/>
		<axis xyz="0 1 0"/>
		<limit effort="1000.0" lower="-0.548" upper="0.548" velocity="0.5"/>
	</joint>

	<link name="bein_rechts_vorne_4a_link">
 		<visual>
			<geometry>
				<box size="0.04 0.03 0.0216"/>
			</geometry>
			<origin rpy="0 0 0" xyz="0 0 0"/>
			<material name="grey"/>
		</visual>
	</link>

	<joint name="bein_rechts_vorne_3d_to_bein_rechts_vorne_4a" type="fixed">
		<parent link="bein_rechts_vorne_3d_link"/>
		<child link="bein_rechts_vorne_4a_link"/>
		<origin xyz="0 0 -0.03578"/>
	</joint>

	<link name="bein_rechts_vorne_4b_link">
 		<visual>
			<geometry>
				<cylinder length="0.082" radius="0.00375"/>
			</geometry>
			<origin rpy="0 0 0" xyz="0 0 0"/>
			<material name="grey"/>
		</visual>
	</link>

	<joint name="bein_rechts_vorne_4a_to_bein_rechts_vorne_4b" type="fixed">
		<parent link="bein_rechts_vorne_4a_link"/>
		<child link="bein_rechts_vorne_4b_link"/>
		<origin xyz="0 0 -0.05153"/>
	</joint>

	<link name="bein_rechts_vorne_4c_link">
 		<visual>
			<geometry>
				<sphere radius="0.004"/>
			</geometry>
			<origin rpy="0 0 0" xyz="0 0 0"/>
			<material name="black"/>
		</visual>
	</link>

	<joint name="bein_rechts_vorne_4b_to_bein_rechts_vorne_4c" type="fixed">
		<parent link="bein_rechts_vorne_4b_link"/>
		<child link="bein_rechts_vorne_4c_link"/>
		<origin xyz="0 0 -0.043"/>
	</joint>



<!-- BEIN RECHTS MITTE -->	

	

		<link name="bein_rechts_mitte_1a_link">
 		<visual>
			<geometry>
				<box size="0.0351 0.0275 0.0063"/>
			</geometry>
			<origin rpy="0 0 0" xyz="0 0 0"/>
			<material name="grey"/>
		</visual>
	</link>

	<joint name="base_mitte_to_bein_rechts_mitte_1a" type="revolute">
		<parent link="base_mitte_link"/>
		<child link="bein_rechts_mitte_1a_link"/>
		<origin xyz="-0.0507505 0 0.02315" rpy="0 0 0"/>
		<axis xyz="0 0 1"/>
		<limit effort="1000.0" lower="-0.548" upper="0.548" velocity="0.5"/>
	</joint>

	<link name="bein_rechts_mitte_1b_link">
 		<visual>
			<geometry>
				<box size="0.0351 0.0275 0.0063"/>
			</geometry>
			<origin rpy="0 0 0" xyz="0 0 0"/>
			<material name="grey"/>
		</visual>
	</link>

	<link name="bein_rechts_mitte_1c_link">
 		<visual>
			<geometry>
				<box size="0.0063 0.0275 0.04"/>
			</geometry>
			<origin rpy="0 0 0" xyz="0 0 0"/>
			<material name="grey"/>
		</visual>
	</link>

	<joint name="bein_rechts_mitte_1a_to_bein_rechts_mitte_1c" type="fixed">
		<parent link="bein_rechts_mitte_1a_link"/>
		<child link="bein_rechts_mitte_1c_link"/>
		<origin xyz="-0.01555 0 -0.0233"/>
	</joint>

	<joint name="bein_rechts_mitte_1b_to_bein_rechts_mitte_1c" type="fixed">
		<parent link="bein_rechts_mitte_1c_link"/>
		<child link="bein_rechts_mitte_1b_link"/>
		<origin xyz="0.01555 0 -0.0233"/>
	</joint>

	<link name="bein_rechts_mitte_2a_link">
 		<visual>
			<geometry>
				<box size="0.0063 0.04 0.0275"/>
			</geometry>
			<origin rpy="0 0 0" xyz="0 0 0"/>
			<material name="grey"/>
		</visual>
	</link>

	<joint name="bein_rechts_mitte_1c_to_bein_rechts_mitte_2a" type="fixed">
		<parent link="bein_rechts_mitte_1c_link"/>
		<child link="bein_rechts_mitte_2a_link"/>
		<origin xyz="-0.0063 0 0"/>
		</joint>

	<link name="bein_rechts_mitte_2b_link">
 		<visual>
			<geometry>
				<box size="0.0351 0.0063 0.0275"/>0
			</geometry>
			<origin rpy="0 0 0" xyz="0 0 0"/>
			<material name="grey"/>
		</visual>
	</link>

	<joint name="bein_rechts_mitte_2a_to_bein_rechts_mitte_2b" type="fixed">
		<parent link="bein_rechts_mitte_2a_link"/>
		<child link="bein_rechts_mitte_2b_link"/>
		<origin xyz="-0.01855 0.01685 0"/>
	</joint>

	<link name="bein_rechts_mitte_2c_link">
 		<visual>
			<geometry>
				<box size="0.0351 0.0063 0.0275"/>0
			</geometry>
			<origin rpy="0 0 0" xyz="0 0 0"/>
			<material name="grey"/>
		</visual>
	</link>

	<joint name="bein_rechts_mitte_2a_to_bein_rechts_mitte_2c" type="fixed">
		<parent link="bein_rechts_mitte_2a_link"/>
		<child link="bein_rechts_mitte_2c_link"/>
		<origin xyz="-0.01855 -0.01685 0"/>
	</joint>

	<link name="bein_rechts_mitte_2d_link">
 		<visual>
			<geometry>
				<box size="0.0505 0.03 0.04"/>
			</geometry>
			<origin rpy="0 0 0" xyz="0 0 0"/>
			<material name="black"/>
		</visual>
	</link>

	<joint name="bein_rechts_mitte_2b_to_bein_rechts_mitte_2d" type="revolute">
		<parent link="bein_rechts_mitte_2b_link"/>
		<child link="bein_rechts_mitte_2d_link"/>
		<origin xyz="-0.0255005 -0.01815 0"/>
		<axis xyz="0 1 0"/>
		<limit effort="1000.0" lower="-0.548" upper="0.548" velocity="0.5"/>
	</joint>

	<link name="bein_rechts_mitte_3a_link">
 		<visual>
			<geometry>
				<box size="0.0063 0.04 0.0275"/>
			</geometry>
			<origin rpy="0 0 0" xyz="0 0 0"/>
			<material name="grey"/>
		</visual>
	</link>

	<joint name="bein_rechts_mitte_2d_to_bein_rechts_mitte_3a" type="fixed">
		<parent link="bein_rechts_mitte_2d_link"/>
		<child link="bein_rechts_mitte_3a_link"/>
		<origin xyz="-0.0284 0 0"/>
	</joint>

	<link name="bein_rechts_mitte_3b_link">
 		<visual>
			<geometry>
				<box size="0.0351 0.0063 0.0275"/>0
			</geometry>
			<origin rpy="0 0 0" xyz="0 0 0"/>
			<material name="grey"/>
		</visual>
	</link>

	<joint name="bein_rechts_mitte_3a_to_bein_rechts_mitte_3b" type="fixed">
		<parent link="bein_rechts_mitte_3a_link"/>
		<child link="bein_rechts_mitte_3b_link"/>
		<origin xyz="-0.01855 0.01685 0"/>
	</joint>

	<link name="bein_rechts_mitte_3c_link">
 		<visual>
			<geometry>
				<box size="0.0351 0.0063 0.0275"/>0
			</geometry>
			<origin rpy="0 0 0" xyz="0 0 0"/>
			<material name="grey"/>
		</visual>
	</link>

	<joint name="bein_rechts_mitte_3a_to_bein_rechts_mitte_3c" type="fixed">
		<parent link="bein_rechts_mitte_3a_link"/>
		<child link="bein_rechts_mitte_3c_link"/>
		<origin xyz="-0.01855 -0.01685 0"/>
	</joint>

	<link name="bein_rechts_mitte_3d_link">
 		<visual>
			<geometry>
				<box size="0.04 0.03 0.0505"/>
			</geometry>
			<origin rpy="0 0 0" xyz="0 0 0"/>
			<material name="black"/>
		</visual>
	</link>

	<joint name="bein_rechts_mitte_3b_to_bein_rechts_mitte_3d" type="revolute">
		<parent link="bein_rechts_mitte_3b_link"/>
		<child link="bein_rechts_mitte_3d_link"/>
		<origin xyz="-0.022505 -0.01815 -0.01"/>
		<axis xyz="0 1 0"/>
		<limit effort="1000.0" lower="-0.548" upper="0.548" velocity="0.5"/>
	</joint>

	<link name="bein_rechts_mitte_4a_link">
 		<visual>
			<geometry>
				<box size="0.04 0.03 0.0216"/>
			</geometry>
			<origin rpy="0 0 0" xyz="0 0 0"/>
			<material name="grey"/>
		</visual>
	</link>

	<joint name="bein_rechts_mitte_3d_to_bein_rechts_mitte_4a" type="fixed">
		<parent link="bein_rechts_mitte_3d_link"/>
		<child link="bein_rechts_mitte_4a_link"/>
		<origin xyz="0 0 -0.03578"/>
	</joint>

	<link name="bein_rechts_mitte_4b_link">
 		<visual>
			<geometry>
				<cylinder length="0.082" radius="0.00375"/>
			</geometry>
			<origin rpy="0 0 0" xyz="0 0 0"/>
			<material name="grey"/>
		</visual>
	</link>

	<joint name="bein_rechts_mitte_4a_to_bein_rechts_mitte_4b" type="fixed">
		<parent link="bein_rechts_mitte_4a_link"/>
		<child link="bein_rechts_mitte_4b_link"/>
		<origin xyz="0 0 -0.05153"/>
	</joint>

	<link name="bein_rechts_mitte_4c_link">
 		<visual>
			<geometry>
				<sphere radius="0.004"/>
			</geometry>
			<origin rpy="0 0 0" xyz="0 0 0"/>
			<material name="black"/>
		</visual>
	</link>

	<joint name="bein_rechts_mitte_4b_to_bein_rechts_mitte_4c" type="fixed">
		<parent link="bein_rechts_mitte_4b_link"/>
		<child link="bein_rechts_mitte_4c_link"/>
		<origin xyz="0 0 -0.043"/>
	</joint>

<!-- BEIN RECHTS HINTEN -->

		<link name="bein_rechts_hinten_1a_link">
 		<visual>
			<geometry>
				<box size="0.0351 0.0275 0.0063"/>
			</geometry>
			<origin rpy="0 0 0" xyz="0 0 0"/>
			<material name="grey"/>
		</visual>
	</link>

	<joint name="base_hinten_to_bein_rechts_hinten_1a" type="revolute">
		<parent link="base_hinten_link"/>
		<child link="bein_rechts_hinten_1a_link"/>
		<origin xyz="-0.0507505 0 0.02315" rpy="0 0 0"/>
		<axis xyz="0 0 1"/>
		<limit effort="1000.0" lower="-0.548" upper="0.548" velocity="0.5"/>
	</joint>

	<link name="bein_rechts_hinten_1b_link">
 		<visual>
			<geometry>
				<box size="0.0351 0.0275 0.0063"/>
			</geometry>
			<origin rpy="0 0 0" xyz="0 0 0"/>
			<material name="grey"/>
		</visual>
	</link>

	<link name="bein_rechts_hinten_1c_link">
 		<visual>
			<geometry>
				<box size="0.0063 0.0275 0.04"/>
			</geometry>
			<origin rpy="0 0 0" xyz="0 0 0"/>
			<material name="grey"/>
		</visual>
	</link>

	<joint name="bein_rechts_hinten_1a_to_bein_rechts_hinten_1c" type="fixed">
		<parent link="bein_rechts_hinten_1a_link"/>
		<child link="bein_rechts_hinten_1c_link"/>
		<origin xyz="-0.01555 0 -0.0233"/>
	</joint>

	<joint name="bein_rechts_hinten_1b_to_bein_rechts_hinten_1c" type="fixed">
		<parent link="bein_rechts_hinten_1c_link"/>
		<child link="bein_rechts_hinten_1b_link"/>
		<origin xyz="0.01555 0 -0.0233"/>
	</joint>

	<link name="bein_rechts_hinten_2a_link">
 		<visual>
			<geometry>
				<box size="0.0063 0.04 0.0275"/>
			</geometry>
			<origin rpy="0 0 0" xyz="0 0 0"/>
			<material name="grey"/>
		</visual>
	</link>

	<joint name="bein_rechts_hinten_1c_to_bein_rechts_hinten_2a" type="fixed">
		<parent link="bein_rechts_hinten_1c_link"/>
		<child link="bein_rechts_hinten_2a_link"/>
		<origin xyz="-0.0063 0 0"/>
		</joint>

	<link name="bein_rechts_hinten_2b_link">
 		<visual>
			<geometry>
				<box size="0.0351 0.0063 0.0275"/>0
			</geometry>
			<origin rpy="0 0 0" xyz="0 0 0"/>
			<material name="grey"/>
		</visual>
	</link>

	<joint name="bein_rechts_hinten_2a_to_bein_rechts_hinten_2b" type="fixed">
		<parent link="bein_rechts_hinten_2a_link"/>
		<child link="bein_rechts_hinten_2b_link"/>
		<origin xyz="-0.01855 0.01685 0"/>
	</joint>

	<link name="bein_rechts_hinten_2c_link">
 		<visual>
			<geometry>
				<box size="0.0351 0.0063 0.0275"/>0
			</geometry>
			<origin rpy="0 0 0" xyz="0 0 0"/>
			<material name="grey"/>
		</visual>
	</link>

	<joint name="bein_rechts_hinten_2a_to_bein_rechts_hinten_2c" type="fixed">
		<parent link="bein_rechts_hinten_2a_link"/>
		<child link="bein_rechts_hinten_2c_link"/>
		<origin xyz="-0.01855 -0.01685 0"/>
	</joint>

	<link name="bein_rechts_hinten_2d_link">
 		<visual>
			<geometry>
				<box size="0.0505 0.03 0.04"/>
			</geometry>
			<origin rpy="0 0 0" xyz="0 0 0"/>
			<material name="black"/>
		</visual>
	</link>

	<joint name="bein_rechts_hinten_2b_to_bein_rechts_hinten_2d" type="revolute">
		<parent link="bein_rechts_hinten_2b_link"/>
		<child link="bein_rechts_hinten_2d_link"/>
		<origin xyz="-0.0255005 -0.01815 0"/>
		<axis xyz="0 1 0"/>
		<limit effort="1000.0" lower="-0.548" upper="0.548" velocity="0.5"/>
	</joint>

	<link name="bein_rechts_hinten_3a_link">
 		<visual>
			<geometry>
				<box size="0.0063 0.04 0.0275"/>
			</geometry>
			<origin rpy="0 0 0" xyz="0 0 0"/>
			<material name="grey"/>
		</visual>
	</link>

	<joint name="bein_rechts_hinten_2d_to_bein_rechts_hinten_3a" type="fixed">
		<parent link="bein_rechts_hinten_2d_link"/>
		<child link="bein_rechts_hinten_3a_link"/>
		<origin xyz="-0.0284 0 0"/>
	</joint>

	

	<link name="bein_rechts_hinten_3b_link">
 		<visual>
			<geometry>
				<box size="0.0351 0.0063 0.0275"/>0
			</geometry>
			<origin rpy="0 0 0" xyz="0 0 0"/>
			<material name="grey"/>
		</visual>
	</link>

	<joint name="bein_rechts_hinten_3a_to_bein_rechts_hinten_3b" type="fixed">
		<parent link="bein_rechts_hinten_3a_link"/>
		<child link="bein_rechts_hinten_3b_link"/>
		<origin xyz="-0.01855 0.01685 0"/>
	</joint>

	<link name="bein_rechts_hinten_3c_link">
 		<visual>
			<geometry>
				<box size="0.0351 0.0063 0.0275"/>0
			</geometry>
			<origin rpy="0 0 0" xyz="0 0 0"/>
			<material name="grey"/>
		</visual>
	</link>

	<joint name="bein_rechts_hinten_3a_to_bein_rechts_hinten_3c" type="fixed">
		<parent link="bein_rechts_hinten_3a_link"/>
		<child link="bein_rechts_hinten_3c_link"/>
		<origin xyz="-0.01855 -0.01685 0"/>
	</joint>

	<link name="bein_rechts_hinten_3d_link">
 		<visual>
			<geometry>
				<box size="0.04 0.03 0.0505"/>
			</geometry>
			<origin rpy="0 0 0" xyz="0 0 0"/>
			<material name="black"/>
		</visual>
	</link>

	<joint name="bein_rechts_hinten_3b_to_bein_rechts_hinten_3d" type="revolute">
		<parent link="bein_rechts_hinten_3b_link"/>
		<child link="bein_rechts_hinten_3d_link"/>
		<origin xyz="-0.022505 -0.01815 -0.01"/>
		<axis xyz="0 1 0"/>
		<limit effort="1000.0" lower="-0.548" upper="0.548" velocity="0.5"/>
	</joint>

	<link name="bein_rechts_hinten_4a_link">
 		<visual>
			<geometry>
				<box size="0.04 0.03 0.0216"/>
			</geometry>
			<origin rpy="0 0 0" xyz="0 0 0"/>
			<material name="grey"/>
		</visual>
	</link>

	<joint name="bein_rechts_hinten_3d_to_bein_rechts_hinten_4a" type="fixed">
		<parent link="bein_rechts_hinten_3d_link"/>
		<child link="bein_rechts_hinten_4a_link"/>
		<origin xyz="0 0 -0.03578"/>
	</joint>

	<link name="bein_rechts_hinten_4b_link">
 		<visual>
			<geometry>
				<cylinder length="0.082" radius="0.00375"/>
			</geometry>
			<origin rpy="0 0 0" xyz="0 0 0"/>
			<material name="grey"/>
		</visual>
	</link>

	<joint name="bein_rechts_hinten_4a_to_bein_rechts_hinten_4b" type="fixed">
		<parent link="bein_rechts_hinten_4a_link"/>
		<child link="bein_rechts_hinten_4b_link"/>
		<origin xyz="0 0 -0.05153"/>
	</joint>

	<link name="bein_rechts_hinten_4c_link">
 		<visual>
			<geometry>
				<sphere radius="0.004"/>
			</geometry>
			<origin rpy="0 0 0" xyz="0 0 0"/>
			<material name="black"/>
		</visual>
	</link>

	<joint name="bein_rechts_hinten_4b_to_bein_rechts_hinten_4c" type="fixed">
		<parent link="bein_rechts_hinten_4b_link"/>
		<child link="bein_rechts_hinten_4c_link"/>
		<origin xyz="0 0 -0.043"/>
	</joint>







	

</robot>
